<?xml version="1.0"?>
<robot name="simbot" xmlns:xacro="http://ros.org/wiki/xacro">

  <!-- Define intertial property macros  -->
  <xacro:macro name="box_inertia" params="m w h d">
    <inertial>
      <origin xyz="0 0 0" rpy="${pi/2} 0 ${pi/2}"/>
      <mass value="${m}"/>
      <inertia ixx="${(m/12) * (h*h + d*d)}" ixy="0.0" ixz="0.0" iyy="${(m/12) * (w*w + d*d)}" iyz="0.0" izz="${(m/12) * (w*w + h*h)}"/>
    </inertial>
  </xacro:macro>

  <xacro:macro name="cylinder_inertia" params="m r h">
    <inertial>
      <origin xyz="0 0 0" rpy="${pi/2} 0 0" />
      <mass value="${m}"/>
      <inertia ixx="${(m/12) * (3*r*r + h*h)}" ixy = "0" ixz = "0" iyy="${(m/12) * (3*r*r + h*h)}" iyz = "0" izz="${(m/2) * (r*r)}"/>
    </inertial>
  </xacro:macro>

  <xacro:macro name="sphere_inertia" params="m r">
    <inertial>
      <mass value="${m}"/>
      <inertia ixx="${(2/5) * m * (r*r)}" ixy="0.0" ixz="0.0" iyy="${(2/5) * m * (r*r)}" iyz="0.0" izz="${(2/5) * m * (r*r)}"/>
    </inertial>
  </xacro:macro>

  <!-- Wheels -->
  <xacro:macro name="wheel" params="prefix x_reflect y_reflect">
    <link name="${prefix}_link">
      <visual>
        <origin xyz="0 0 0" rpy="${pi/2} 0 0"/>
        <geometry>
            <cylinder radius="${wheel_radius}" length="${wheel_width}"/>
        </geometry>
        <material name="Gray">
          <color rgba="0.3 0.3 0.3 1.0"/>
        </material>
      </visual>

      <collision>
        <origin xyz="0 0 0" rpy="${pi/2} 0 0"/>
        <geometry>
          <cylinder radius="${wheel_radius}" length="${wheel_width}"/>
        </geometry>
      </collision>

      <xacro:cylinder_inertia m="0.25" r="${wheel_radius}" h="${wheel_width}"/>
    </link>

    <joint name="${prefix}_joint" type="continuous">
      <parent link="base_link"/>
      <child link="${prefix}_link"/>
      <origin xyz="${x_reflect*wheel_xoff} ${y_reflect*(wheel_yoff)} 0" rpy="0 0 0"/>
      <axis xyz="0 1 0"/>
      <dynamics friction="0.5" damping="0.1" />
    </joint>
  </xacro:macro>

  <xacro:macro name="rgb_cam" params="name x z th">
    <link name="${name}_link">
      <origin xyz="0 0 0" rpy="0 0 0"/>
      <visual>
        <origin xyz="0 0 0" rpy="${pi/2} 0 ${pi/2}"/>
        <geometry>
            <cylinder radius="0.007" length="0.03"/>
        </geometry>
        <material name="Black">
          <color rgba="0.0 0.0 0.0 1.0"/>
        </material>
      </visual>

      <collision>
        <origin xyz="0 0 0" rpy="${pi/2} 0 ${pi/2}"/>
        <geometry>
          <cylinder radius="0.007" length="0.03"/>
        </geometry>
      </collision>

      <xacro:cylinder_inertia m="0.005" r="0.007" h="0.03"/>
    </link>

    <joint name="${name}_base_link_joint" type="fixed">
      <parent link="base_link"/>
      <child link="${name}_link"/>
      <origin xyz="${x} 0 ${z}" rpy="0 ${th} 0"/>
    </joint>

    <link name="${name}_frame"/>
    <joint name="${name}_joint" type="fixed">
      <parent link="${name}_link"/>
      <child link="${name}_frame"/>
      <origin xyz="0 0 0" rpy="0 0 0"/>
    </joint>

    <link name="${name}_optical_frame"/>
    <joint name="${name}_optical_joint" type="fixed">
      <parent link="${name}_frame"/>
      <child link="${name}_optical_frame"/>
      <origin xyz="0 0 0" rpy="-1.57 0 -1.57"/>
    </joint>

  </xacro:macro>

</robot>
